<?xml version="1.0"?>
<robot
    xmlns:gazebo="http://playerstage.sourceforge.net/gazebo/xmlschema/#gz"
    xmlns:model="http://playerstage.sourceforge.net/gazebo/xmlschema/#model"
    xmlns:sensor="http://playerstage.sourceforge.net/gazebo/xmlschema/#sensor"
    xmlns:body="http://playerstage.sourceforge.net/gazebo/xmlschema/#body"
    xmlns:geom="http://playerstage.sourceforge.net/gazebo/xmlschema/#geom"
    xmlns:joint="http://playerstage.sourceforge.net/gazebo/xmlschema/#joint"
    xmlns:controller="http://playerstage.sourceforge.net/gazebo/xmlschema/#controller"
    xmlns:interface="http://playerstage.sourceforge.net/gazebo/xmlschema/#interface"
    xmlns:rendering="http://playerstage.sourceforge.net/gazebo/xmlschema/#rendering"
    xmlns:physics="http://playerstage.sourceforge.net/gazebo/xmlschema/#physics"
    xmlns:xacro="http://www.ros.org/wiki/xacro"
    name="ackermann"
    >

    <property name="M_PI" value="3.1415926535897931" />
    <property name="SCALE" value="0.4000000000000000" />

    <material name="Red">
      <color rgba="1.0 0 0 1.0"/>
    </material>
    <material name="Green">
      <color rgba="0 1.0 0 1.0"/>
    </material>
    <material name="Blue">
      <color rgba="0 0 1.0 0.5"/>
    </material>
    <!-- Main body -->
    <link name="base_link">
        <inertial>
            <mass value="1.8" />
            <origin xyz="0 0 -1.25" />
            <inertia  ixx="0.4" ixy="0.0"  ixz="0.0"  iyy="0.4"  iyz="0.0"  izz="0.4" />
        </inertial>
        <visual>
            <origin xyz="0 0 -0.043" rpy="0 0 1.57" />
            <geometry>
                <mesh filename="package://CATEC_ugv/Media/models/cars/Lincoln/lincoln_chasis.dae" scale="0.02 0.02 0.02"/>
            </geometry>
        </visual>
        <collision>
            <origin xyz="0 0 0" rpy="0 0 0" />
            <geometry>
                <box size="${SCALE*0.4} ${SCALE*0.15} ${SCALE*0.1}" />
            </geometry>
        </collision>
    </link>
    <!--gazebo reference="base_link">
        <material>Gazebo/Blue</material>
    </gazebo-->

    <!-- Front link of Ackermann -->
    <joint name="front_joint" type="fixed">
      <parent link="base_link"/>
      <child link="front_link"/>
      <origin xyz="${SCALE*0.16} ${SCALE*0.0} ${SCALE*(-0.1)}"/>
    </joint>
    <link name="front_link">
        <inertial>
            <mass value="0.01" />
            <origin xyz="0 0 0" />
            <inertia  ixx="0.01" ixy="0.0"  ixz="0.0"  iyy="0.01"  iyz="0.0"  izz="0.01" />
        </inertial>
        <visual>
            <geometry>
                <box size="${SCALE*0.00} ${SCALE*0.00} ${SCALE*0.00}" />
            </geometry>
            <material name="Red"/>
        </visual>
        <collision>
            <geometry>
                <box size="${SCALE*0.02} ${SCALE*0.15} ${SCALE*0.005}" />
            </geometry>
        </collision>
    </link>
    <gazebo reference="front_link">
        <material>Gazebo/Red</material>
    </gazebo>

    <!-- a link aligned with the steer direction -->
    <joint name="steer_joint" type="revolute" >
        <limit lower="-0.6" upper="0.6" effort="100" velocity="10" />
        <axis xyz="0 0 1" />
        <parent link="front_link" />
        <child link="steer_link" />
        <origin xyz="0.0 0.0 0.0" rpy="0 0 0" />
    </joint>
    <link name="steer_link">
        <inertial>
            <mass value="0.01" />
            <origin xyz="0 0 0" />
            <inertia  ixx="0.01" ixy="0.0"  ixz="0.0"  iyy="0.01"  iyz="0.0"  izz="0.01" />
        </inertial>
        <visual>
            <origin xyz="${SCALE*(-0.02)} 0 0" />
            <geometry>
                <box size="${SCALE*0.00} ${SCALE*0.00} ${SCALE*0.00}" />
            </geometry>
            <material name="Red"/>
        </visual>
        <collision>
            <origin xyz="${SCALE*(-0.02)} 0 0" />
            <geometry>
                <box size="${SCALE*0.04} ${SCALE*0.02} ${SCALE*0.005}" />
            </geometry>
        </collision>
    </link>
    <gazebo reference="steer_link">
        <material>Gazebo/Red</material>
    </gazebo>

    <!-- the left Ackermann bar -->
    <joint name="front_left_bar_joint" type="revolute" >
        <limit lower="-0.6" upper="0.6" effort="100" velocity="10" />
        <axis xyz="0 0 1" />
        <parent link="front_link" />
        <child link="front_left_bar_link" />
        <origin xyz="0.0 ${SCALE*0.06} 0.0" rpy="0 0 0" />
    </joint>
    <link name="front_left_bar_link">
        <inertial>
            <mass value="0.01" />
            <origin xyz="0 0 0" />
            <inertia  ixx="0.01" ixy="0.0"  ixz="0.0"  iyy="0.01"  iyz="0.0"  izz="0.01" />
        </inertial>
        <visual>
            <origin xyz="${SCALE*(-0.02)} 0 0" />
            <geometry>
                <box size="${SCALE*0.00} ${SCALE*0.00} ${SCALE*0.00}" />
            </geometry>
            <material name="Red"/>
        </visual>
        <collision>
            <origin xyz="${SCALE*(-0.02)} 0 0" />
            <geometry>
                <box size="${SCALE*0.04} ${SCALE*0.02} ${SCALE*0.005}" />
            </geometry>
        </collision>
    </link>
    <gazebo reference="front_left_bar_link">
        <material>Gazebo/Red</material>
    </gazebo>

    <!-- the right Ackermann bar -->
    <joint name="front_right_bar_joint" type="revolute" >
        <limit lower="-0.6" upper="0.6" effort="100" velocity="10" />
        <axis xyz="0 0 1" />
        <parent link="front_link" />
        <child link="front_right_bar_link" />
        <origin xyz="0.0 ${SCALE*(-0.06)} 0.0" rpy="0 0 0" />
    </joint>
    <link name="front_right_bar_link">
        <inertial>
            <mass value="0.01" />
            <origin xyz="0 0 0" />
            <inertia  ixx="0.01" ixy="0.0"  ixz="0.0"  iyy="0.01"  iyz="0.0"  izz="0.01" />
        </inertial>
        <visual>
            <origin xyz="${SCALE*(-0.02)} 0 0" />
            <geometry>
                <box size="${SCALE*0.00} ${SCALE*0.00} ${SCALE*0.00}" />
            </geometry>
            <material name="Red"/>
        </visual>
        <collision>
            <origin xyz="${SCALE*(-0.02)} 0 0" />
            <geometry>
                <box size="${SCALE*0.04} ${SCALE*0.02} ${SCALE*0.005}" />
            </geometry>
        </collision>
    </link>
    <gazebo reference="front_right_bar_link">
        <material>Gazebo/Red</material>
    </gazebo>

   <!-- the front left wheel -->
    <joint name="front_left_wheel_joint" type="continuous" >
        <axis xyz="0 1 0" />
        <parent link="front_left_bar_link" />
        <child link="front_left_wheel_link" />
        <origin xyz="0.0015 ${(SCALE*0.04)-0.006} 0.01" rpy="0 0 0" />
    </joint>
    <link name="front_left_wheel_link">
        <inertial>
            <mass value="0.01" />
            <origin xyz="0 0 0" />
            <inertia  ixx="0.01" ixy="0.0"  ixz="0.0"  iyy="0.01"  iyz="0.0"  izz="0.01" />
        </inertial>
        <visual>
            <origin xyz="0.0 0.0 0.0" rpy="0 ${-M_PI/2} 0" />
            <geometry>
                <mesh filename="package://CATEC_ugv/Media/models/cars/Lincoln/wheelCentered.dae" scale="0.02 0.02 0.02"/>
            </geometry>
        </visual>
        <collision>
            <origin xyz="0 0 0" rpy="${M_PI/2} 0 0" />
            <geometry>
                <cylinder radius="${SCALE*0.037}" length="0.02" />
            </geometry>
        </collision>
    </link>
    <!--gazebo reference="front_left_wheel_link">
        <material>Gazebo/Green</material>
    </gazebo-->

   <!-- the front right wheel -->
    <joint name="front_right_wheel_joint" type="continuous" >
        <axis xyz="0 1 0" />
        <parent link="front_right_bar_link" />
        <child link="front_right_wheel_link" />
        <origin xyz="0.0015 ${(SCALE*(-0.04))+0.006} 0.01" rpy="0 0 0" />
    </joint>
    <link name="front_right_wheel_link">
        <inertial>
            <mass value="0.01" />
            <origin xyz="0 0 0" />
            <inertia  ixx="0.01" ixy="0.0"  ixz="0.0"  iyy="0.01"  iyz="0.0"  izz="0.01" />
        </inertial>
        <visual> <!-- longitudinal altura  -->
        <origin xyz="0.0 0.0 0.0" rpy="0 ${M_PI/2} 0" />
        <geometry>
            <mesh filename="package://CATEC_ugv/Media/models/cars/Lincoln/wheelCentered.dae" scale="0.02 0.02 0.02"/>
            </geometry>
        </visual>
        <collision>
            <origin xyz="0 0 0" rpy="${M_PI/2} 0 0" />
            <geometry>
                <cylinder radius="${SCALE*0.037}" length="0.02" />
            </geometry>
        </collision>
    </link>
    <gazebo reference="front_right_wheel_link">
        <turnGravityOff>false</turnGravityOff>
    </gazebo>

   <!-- the Ackerman bar -->
    <joint name="ackermann_joint" type="revolute" >
        <limit lower="-0.6" upper="0.6" effort="100" velocity="10" />
        <axis xyz="0 0 1" />
        <parent link="steer_link" />
        <child link="ackermann_bar_link" />
        <origin xyz="${SCALE*(-0.04)} 0 0" rpy="0 0 0" />
    </joint>
    <link name="ackermann_bar_link">
        <inertial>
            <mass value="0.01" />
            <origin xyz="0 0 0" />
            <inertia  ixx="0.01" ixy="0.0"  ixz="0.0"  iyy="0.01"  iyz="0.0"  izz="0.01" />
        </inertial>
        <visual>
            <geometry>
                <box size="${SCALE*0.00} ${SCALE*0.0} ${SCALE*0.00}" />
            </geometry>
            <material name="Red"/>
        </visual>
        <collision>
            <geometry>
                <box size="${SCALE*0.02} ${SCALE*0.15} ${SCALE*0.01}" />
            </geometry>
        </collision>
    </link>
    <gazebo reference="front_link">
        <material>Gazebo/Red</material>
    </gazebo>
    <gazebo reference="ackermann_bar_link">
        <material>Gazebo/Blue</material>
    </gazebo>

   <!-- Gazebo Ackermann loop joints -->
    <gazebo>
      <joint:hinge name="ackermann_left_bar_joint">
        <body1>ackermann_bar_link</body1>
        <body2>front_left_bar_link</body2>
        <anchor>ackermann_bar_link</anchor>
        <axis>0 0 1</axis>
        <anchorOffset>0 ${SCALE*0.06} 0</anchorOffset>
      </joint:hinge>
    </gazebo>
    <gazebo>
      <joint:hinge name="ackermann_right_bar_joint">
        <body1>ackermann_bar_link</body1>
        <body2>front_right_bar_link</body2>
        <anchor>ackermann_bar_link</anchor>
        <axis>0 0 1</axis>
        <anchorOffset>0 ${SCALE*(-0.06)} 0</anchorOffset>
      </joint:hinge>
    </gazebo>

   <!-- the back left wheel -->
    <joint name="back_left_wheel_joint" type="continuous" >
        <axis xyz="0 1 0" />
        <parent link="base_link" />
        <child link="back_left_wheel_link" />
        <origin xyz="${(SCALE*(-0.16))+0.006} ${(SCALE*0.1)-0.006} ${(SCALE*(-0.1))+0.01}" rpy="0 0 0" />
    </joint>
    <link name="back_left_wheel_link">
        <inertial>
            <mass value="0.01" />
            <origin xyz="0 0 0" />
            <inertia  ixx="0.01" ixy="0.0"  ixz="0.0"  iyy="0.01"  iyz="0.0"  izz="0.01" />
        </inertial>
        <visual>
        <origin xyz="0.0 0.0 0.0" rpy="0 ${-M_PI/2} 0" />
        <geometry>
            <mesh filename="package://CATEC_ugv/Media/models/cars/Lincoln/wheelCentered.dae" scale="0.02 0.02 0.02"/>
            </geometry>
        </visual>
        <collision>
            <origin xyz="0 0 0" rpy="${M_PI/2} 0 0" />
            <geometry>
                <cylinder radius="${SCALE*0.037}" length="0.02" />
            </geometry>
        </collision>
    </link>
    <!--gazebo reference="back_left_wheel_link">
        <material>Gazebo/Green</material>
    </gazebo-->

   <!-- the back right wheel -->
    <joint name="back_right_wheel_joint" type="continuous" >
        <axis xyz="0 1 0" />
        <parent link="base_link" />
        <child link="back_right_wheel_link" />
        <origin xyz="${(SCALE*(-0.16))+0.006} ${(SCALE*(-0.1))+0.006} ${(SCALE*(-0.1))+0.01}" rpy="0 0 0" />
    </joint>
    <link name="back_right_wheel_link">
        <inertial>
            <mass value="0.01" />
            <origin xyz="0 0 0" />
            <inertia  ixx="0.01" ixy="0.0"  ixz="0.0"  iyy="0.01"  iyz="0.0"  izz="0.01" />
        </inertial>
        <visual>
        <origin xyz="0.0 0.0 0.0" rpy="0 ${M_PI/2} 0" />
        <geometry>
            <mesh filename="package://CATEC_ugv/Media/models/cars/Lincoln/wheelCentered.dae" scale="0.02 0.02 0.02"/>
            </geometry>
        </visual>
        <collision>
            <origin xyz="0 0 0" rpy="${M_PI/2} 0 0" />
            <geometry>
                <cylinder radius="${SCALE*0.037}" length="0.02" />
            </geometry>
        </collision>
    </link>
    <!--gazebo reference="back_right_wheel_link">
        <material>Gazebo/Green</material>
    </gazebo-->

    <!-- Ackermann plugin -->
    <gazebo>
      <controller:ackermann_plugin name="ackermann_controller"
                    plugin="libackermann_plugin.so">
   <alwaysOn>true</alwaysOn>
   <update>100</update>
   <updateRate>100.0</updateRate>
   <leftJoint>back_left_wheel_joint</leftJoint>
   <rightJoint>back_right_wheel_joint</rightJoint>
   <steerJoint>steer_joint</steerJoint>
   <wheelSeparationWidth>${SCALE*0.16}</wheelSeparationWidth>
   <wheelSeparationLength>${SCALE*0.45}</wheelSeparationLength>
        <!-- Shouldn't this wheel diameter include the tire?
             (40 cm is about right for the bare rim)
          -->
   <wheelDiameter>${SCALE*0.041}</wheelDiameter>
   <driveTorque>5</driveTorque>
   <steerTorque>5</steerTorque>
   <interface:position name="position_iface_0" />
   <robotNamespace>/</robotNamespace>
   <topicName>pilot/drive</topicName>
      </controller:ackermann_plugin>

     <canonicalBody>base_footprint</canonicalBody>
    </gazebo>
</robot>
